The .catch() function takes only one argument, onRejected. In the case of a rejected promise, 
this failure handler will be invoked with the reason for rejection. Using .catch() accomplishes 
the same thing as using a .then() with only a failure handler.The .catch() function 
takes only one argument, onRejected. 
In the case of a rejected promise, this failure handler will be invoked with the reason for rejection.
Using .catch() accomplishes the same thing as using a .then() with only a failure handler.